name: test workflow fail once py raises exception

on:
  push:
    branches:
      - main

jobs:
  run:
    runs-on: ubuntu-latest
    steps:
      - uses: actions/checkout@v3
      - name: Run
        run: |
          echo "abc"  # called
          python test.py  # an exception occurred
          echo "123"  # not called
          echo "987"  # not called
          echo "aaa"  # not called
          echo "bbb"  # not called